#VRML_SIM R2021b utf8
WorldInfo {
  coordinateSystem "NUE"
  contactProperties [
    ContactProperties {
    }
  ]
}
Viewpoint {
  orientation -0.9999711210463741 -0.0022268532736470638 0.007266236835926363 0.8306200154397877
  position -0.3458949271421063 2.639048187269788 3.1734079828239175
}
Background {
  skyColor [
    1 1 1
  ]
  luminosity 0
}
DEF floorSolid Solid {
  scale 2 2 2
  children [
    DEF Floor Shape {
      appearance Appearance {
        material Material {
          diffuseColor 0.113725 0.223529 0.337255
          emissiveColor 0.121569 0.247059 0.368627
          specularColor 0.109804 0.223529 0.333333
        }
      }
      geometry Box {
        size 5 0.1 5
      }
    }
  ]
  name "solid(1)"
  boundingObject DEF Floor Shape {
    appearance Appearance {
      material Material {
        diffuseColor 0.113725 0.223529 0.337255
        emissiveColor 0.121569 0.247059 0.368627
        specularColor 0.109804 0.223529 0.333333
      }
    }
    geometry Box {
      size 5 0.1 5
    }
  }
}
DEF wall1 Solid {
  translation 0 0.23 4.93
  scale 2 2 2
  children [
    DEF wall1Shape Shape {
      appearance Appearance {
        material Material {
          diffuseColor 0.666667 0 0
          emissiveColor 0.333333 0.666667 1
        }
      }
      geometry Box {
        size 5 0.3 0.1
      }
    }
  ]
  boundingObject USE wall1Shape
}
DEF wall2 Solid {
  translation -4.9 0.23 0.010002
  rotation 0 1 0 -1.5707953071795862
  scale 2 2 2
  children [
    DEF wall2Shape Shape {
      appearance Appearance {
        material Material {
          emissiveColor 0.333333 0.333333 1
        }
      }
      geometry Box {
        size 5 0.3 0.1
      }
    }
  ]
  boundingObject USE wall2Shape
}
DEF wall3 Solid {
  translation 4.91 0.24 0.00999476
  rotation 0 1 0 -1.5707953071795862
  scale 2 2 2
  children [
    DEF wall3Shape Shape {
      appearance Appearance {
        material Material {
          emissiveColor 0.333333 0.333333 1
        }
      }
      geometry Box {
        size 5 0.3 0.1
      }
    }
  ]
  boundingObject USE wall3Shape
}
DEF wall4 Solid {
  translation 0 0.24 -4.92
  scale 2 2 2
  children [
    DEF wall4Shape Shape {
      appearance Appearance {
        material Material {
          emissiveColor 0.333333 0.333333 1
        }
      }
      geometry Box {
        size 5 0.3 0.1
      }
    }
  ]
  boundingObject USE wall4Shape
}
DirectionalLight {
  direction -1 -1 -1
  castShadows TRUE
}
DEF sylinder Solid {
  translation -2.52 0.48 2.22
  children [
    DEF sylinderShape Shape {
      appearance Appearance {
        material Material {
          emissiveColor 0.556863 0.317647 0.580392
        }
      }
      geometry Cylinder {
        height 1
        radius 0.3
        subdivision 24
      }
    }
  ]
  boundingObject USE sylinderShape
}
DEF sphere Solid {
  translation 4.312524755813838 0.5921525205756817 0.639713187841216
  rotation -0.34232952035000364 0.8538208101548007 0.3921740986392858 2.4993181949769405
  children [
    DEF shareShape Shape {
      appearance Appearance {
        material Material {
          emissiveColor 0.556863 0.317647 0.580392
        }
      }
      geometry Sphere {
        radius 0.5
        subdivision 2
      }
    }
  ]
  boundingObject USE shareShape
  physics Physics {
    density -1
    mass 5
  }
  linearVelocity 0 -4.287721356237713e-06 0
}
DEF cone Solid {
  translation -3.028125656915539 0.6099578866809574 -1.968571689816688
  rotation -0.044896577257164165 -0.06709600827201674 0.9967358842865812 0.00010532483862375876
  children [
    DEF coneShape Shape {
      appearance Appearance {
        material Material {
          emissiveColor 0.556863 0.317647 0.580392
        }
      }
      geometry Cone {
        bottomRadius 0.5
        height 1
      }
    }
  ]
  boundingObject Group {
    children [
      Transform {
        translation 0 -0.31 0
        children [
          Cylinder {
            height 0.4
            radius 0.5
          }
        ]
      }
      Transform {
        translation 0 0.13 0
        children [
          Cylinder {
            height 0.6
            radius 0.2
          }
        ]
      }
    ]
  }
  physics Physics {
    density -1
    mass 0.5
  }
  linearVelocity 3.700815411493038e-05 -2.563829549831098e-05 -5.4938325934252184e-05
  angularVelocity -0.00019268881092759243 1.4980668110368405e-10 -0.00012980349915850452
}
DEF wheel Solid {
  translation -0.8 -0.25 -1.93
  children [
    DEF pipe Transform {
      translation 3.47 0.89 0
      children [
        Shape {
          appearance Appearance {
            material Material {
              emissiveColor 0.556863 0.317647 0.580392
            }
          }
          geometry Cylinder {
            height 0.5
            radius 0.2
            subdivision 24
          }
        }
      ]
    }
    DEF wheel1 Transform {
      translation 3.47 0.48 0
      children [
        Shape {
          appearance Appearance {
            material Material {
              emissiveColor 0.556863 0.317647 0.580392
            }
          }
          geometry Cylinder {
            height 0.4
            radius 0.4
            subdivision 24
          }
        }
      ]
    }
  ]
  boundingObject Group {
    children [
      USE wheel1
      USE pipe
    ]
  }
}
Robot {
  translation 1.5784799132747616e-05 0.24214258093107466 0.5099899179113351
  rotation -0.036113854243943984 0.003182731605727543 -0.9993426137972767 1.7752844056037187e-05
  scale 4 4 4
  children [
    DistanceSensor {
      translation 0.02 0 0.1
      rotation 0 -1 0 1.27
      children [
        Shape {
          appearance PBRAppearance {
            baseColor 1 0.666667 0
            metalness 0
          }
          geometry Box {
            size 0.01 0.01 0.01
          }
        }
      ]
      name "ds_right"
    }
    DistanceSensor {
      translation -0.02 0 0.1
      rotation 0 -1 0 1.87
      children [
        Shape {
          appearance PBRAppearance {
            baseColor 1 0.666667 0
            metalness 0
          }
          geometry Box {
            size 0.01 0.01 0.01
          }
        }
      ]
      name "ds_left"
    }
    HingeJoint {
      jointParameters HingeJointParameters {
        position -1.3264076174248233e-09
        anchor -0.06 6.27628e-05 0.05
      }
      device [
        RotationalMotor {
          name "wheel1"
        }
      ]
      endPoint Solid {
        translation -0.06 0 0.05000000000008325
        rotation -6.637321460682838e-10 6.632038087124059e-10 1 1.5699999999999994
        children [
          DEF robot_wheel Shape {
            appearance PBRAppearance {
              baseColor 1 0.643137 0.0235294
              metalness 0
            }
            geometry Cylinder {
              height 0.02
              radius 0.04
            }
          }
        ]
        boundingObject USE robot_wheel
        physics Physics {
        }
      }
    }
    HingeJoint {
      jointParameters HingeJointParameters {
        position -2.040417779640691e-08
        anchor 0.06 6.28043e-05 0.05
      }
      device [
        RotationalMotor {
          name "wheel2"
        }
      ]
      endPoint Solid {
        translation 0.06 0 0.05000000000128147
        rotation -5.06475040268469e-09 5.063211588194048e-09 1 1.5699999802009506
        children [
          DEF robot_wheel Shape {
            appearance PBRAppearance {
              baseColor 1 0.643137 0.0235294
              metalness 0
            }
            geometry Cylinder {
              height 0.02
              radius 0.04
            }
          }
        ]
        name "solid(1)"
        boundingObject USE robot_wheel
        physics Physics {
        }
      }
    }
    HingeJoint {
      jointParameters HingeJointParameters {
        position -7.172732589032602e-11
        anchor 0.06 0 -0.05
      }
      device [
        RotationalMotor {
          name "wheel3"
        }
      ]
      endPoint Solid {
        translation 0.06 0 -0.05
        rotation -5.243089337574618e-09 5.2348412910596285e-09 1 1.569999940206794
        children [
          DEF robot_wheel Shape {
            appearance PBRAppearance {
              baseColor 1 0.643137 0.0235294
              metalness 0
            }
            geometry Cylinder {
              height 0.02
              radius 0.04
            }
          }
        ]
        name "solid(2)"
        boundingObject USE robot_wheel
        physics Physics {
        }
      }
    }
    HingeJoint {
      jointParameters HingeJointParameters {
        position -2.054826563474576e-08
        anchor -0.06 6.27638e-05 -0.05
      }
      device [
        RotationalMotor {
          name "wheel4"
        }
      ]
      endPoint Solid {
        translation -0.06 0 -0.04999999999871031
        rotation -1.5114991501971213e-08 1.5105425386421468e-08 0.9999999999999998 1.5699999801882387
        children [
          DEF robot_wheel Shape {
            appearance PBRAppearance {
              baseColor 1 0.666667 0
              metalness 0
            }
            geometry Cylinder {
              height 0.02
              radius 0.04
            }
          }
        ]
        name "solid(3)"
        boundingObject USE robot_wheel
        physics Physics {
        }
      }
    }
    DEF body Shape {
      appearance PBRAppearance {
        baseColor 0 1 0
        metalness 0
      }
      geometry Box {
        size 0.1 0.05 0.2
      }
    }
  ]
  boundingObject USE body
  physics Physics {
  }
  linearVelocity -1.9694825846506138e-07 2.615966084249521e-07 4.4209800128111755e-07
  angularVelocity 2.8477066408315223e-06 1.2088189746079326e-09 1.2177073265672185e-06
}
