#VRML_SIM R2021b utf8
WorldInfo {
  coordinateSystem "NUE"
  contactProperties [
    ContactProperties {
    }
  ]
}
Viewpoint {
  orientation -0.24867557420007136 0.9253619564757737 0.2861218417101241 1.7654607629037649
  position 13.332008021239693 8.703512964443899 -2.576705152191001
}
Background {
  skyColor [
    1 1 1
  ]
  luminosity 0
}
DEF floorSolid Solid {
  rotation 0 0 1 4.692820414042842e-06
  scale 2 2 2
  children [
    DEF Floor Shape {
      appearance Appearance {
        material Material {
          diffuseColor 0.113725 0.223529 0.337255
          emissiveColor 0.121569 0.247059 0.368627
          specularColor 0.109804 0.223529 0.333333
        }
      }
      geometry Box {
        size 5 0.1 5
      }
    }
  ]
  name "solid(1)"
  boundingObject DEF Floor Shape {
    appearance Appearance {
      material Material {
        diffuseColor 0.113725 0.223529 0.337255
        emissiveColor 0.121569 0.247059 0.368627
        specularColor 0.109804 0.223529 0.333333
      }
    }
    geometry Box {
      size 5 0.1 5
    }
  }
}
DEF wall1 Solid {
  translation 0 0.23 4.93
  scale 2 2 2
  children [
    DEF wall1Shape Shape {
      appearance Appearance {
        material Material {
          diffuseColor 0.666667 0 0
          emissiveColor 0.333333 0.666667 1
        }
      }
      geometry Box {
        size 5 0.3 0.1
      }
    }
  ]
  boundingObject USE wall1Shape
}
DEF wall2 Solid {
  translation -4.9 0.23 0.010002
  rotation 0 1 0 -1.5707953071795862
  scale 2 2 2
  children [
    DEF wall2Shape Shape {
      appearance Appearance {
        material Material {
          emissiveColor 0.333333 0.333333 1
        }
      }
      geometry Box {
        size 5 0.3 0.1
      }
    }
  ]
  boundingObject USE wall2Shape
}
DEF wall3 Solid {
  translation 4.91 0.24 0.00999476
  rotation 0 1 0 -1.5707953071795862
  scale 2 2 2
  children [
    DEF wall3Shape Shape {
      appearance Appearance {
        material Material {
          emissiveColor 0.333333 0.333333 1
        }
      }
      geometry Box {
        size 5 0.3 0.1
      }
    }
  ]
  boundingObject USE wall3Shape
}
DEF wall4 Solid {
  translation 0 0.24 -4.92
  scale 2 2 2
  children [
    DEF wall4Shape Shape {
      appearance Appearance {
        material Material {
          emissiveColor 0.333333 0.333333 1
        }
      }
      geometry Box {
        size 5 0.3 0.1
      }
    }
  ]
  boundingObject USE wall4Shape
}
DirectionalLight {
  direction -1 -1 -1
  castShadows TRUE
}
DEF sylinder Solid {
  translation -2.1 0.48 2.22
  children [
    DEF sylinderShape Shape {
      appearance Appearance {
        material Material {
          emissiveColor 0.556863 0.317647 0.580392
        }
      }
      geometry Cylinder {
        height 1
        radius 0.3
        subdivision 24
      }
    }
  ]
  boundingObject USE sylinderShape
  recognitionColors [
    1 0 0
  ]
}
DEF sphere Solid {
  translation -0.04751804780448891 0.5921517774030282 1.5559675697342776
  rotation 0.6654162084259466 0.6489912360500834 0.368824680701037 3.017668520708393
  children [
    DEF shareShape Shape {
      appearance Appearance {
        material Material {
          emissiveColor 0.556863 0.317647 0.580392
        }
      }
      geometry Sphere {
        radius 0.5
        subdivision 2
      }
    }
  ]
  boundingObject USE shareShape
  physics Physics {
    density -1
    mass 5
  }
  recognitionColors [
    1 0 0
  ]
}
DEF cone Solid {
  translation -2.5312293561457575 0.609934768466903 0.7182859789693096
  rotation 0.008779609554682662 0.999739379976898 0.021073456751913706 0.004107514394628761
  children [
    DEF coneShape Shape {
      appearance Appearance {
        material Material {
          emissiveColor 0.556863 0.317647 0.580392
        }
      }
      geometry Cone {
        bottomRadius 0.5
        height 1
      }
    }
  ]
  boundingObject Group {
    children [
      Transform {
        translation 0 -0.31 0
        children [
          Cylinder {
            height 0.4
            radius 0.5
          }
        ]
      }
      Transform {
        translation 0 0.13 0
        children [
          Cylinder {
            height 0.6
            radius 0.2
          }
        ]
      }
    ]
  }
  physics Physics {
    density -1
    mass 0.5
  }
  recognitionColors [
    1 0 0
  ]
}
Robot {
  translation -2.5777843768271937 0.2412848105635552 -0.46708117167250385
  rotation 0.0013652017945921168 -0.9999972023813009 0.0019316970859649973 2.0243007748643183
  scale 4 4 4
  children [
    Solid {
      translation 0 0.14 0
      children [
        Shape {
          appearance PBRAppearance {
            baseColor 1 0.666667 0
            metalness 0
          }
          geometry Box {
            size 0.03 0.25 0.03
          }
        }
        Camera {
          rotation 0 1 0 3.14159
          name "CAM"
          fieldOfView 1
          width 640
          height 640
          recognition Recognition {
            frameThickness 3
          }
        }
      ]
      name "camera"
    }
    DistanceSensor {
      translation 0.02 0 0.1
      rotation 0 -1 0 1.27
      children [
        Shape {
          appearance PBRAppearance {
            baseColor 1 0.666667 0
            metalness 0
          }
          geometry Box {
            size 0.01 0.01 0.01
          }
        }
      ]
      name "ds_right"
      physics Physics {
      }
    }
    DistanceSensor {
      translation -0.02 0 0.1
      rotation 0 -1 0 1.87
      children [
        Shape {
          appearance PBRAppearance {
            baseColor 1 0.666667 0
            metalness 0
          }
          geometry Box {
            size 0.01 0.01 0.01
          }
        }
      ]
      name "ds_left"
      physics Physics {
      }
    }
    HingeJoint {
      jointParameters HingeJointParameters {
        position 200.2936776530633
        anchor -0.06 2.71051e-20 0.05
      }
      device [
        RotationalMotor {
          name "wheel2"
        }
      ]
      endPoint Solid {
        translation -0.06000001884018633 9.197238874985516e-05 0.04991096243556153
        rotation -0.35116252880076826 0.35088298341119395 0.8680817993246429 1.7110076050697933
        children [
          DEF robot_wheel Shape {
            appearance PBRAppearance {
              baseColor 1 0.643137 0.0235294
              metalness 0
            }
            geometry Cylinder {
              height 0.02
              radius 0.04
            }
          }
        ]
        boundingObject USE robot_wheel
        physics Physics {
        }
        linearVelocity -0.14384236242762485 5.233021946888801e-05 -0.07022573823181155
        angularVelocity -0.43888436407068976 -0.0002874845958918127 0.8987459101850168
      }
    }
    HingeJoint {
      jointParameters HingeJointParameters {
        position 283.09839857720544
        anchor 0.06 6.27425e-05 0.05
      }
      device [
        RotationalMotor {
          name "wheel1"
        }
      ]
      endPoint Solid {
        translation 0.05999998171848761 0.0001246846242769987 0.05002284180791755
        rotation -0.17404217539919528 0.17390362457030833 -0.9692609816471643 4.681968694482183
        children [
          DEF robot_wheel Shape {
            appearance PBRAppearance {
              baseColor 1 0.643137 0.0235294
              metalness 0
            }
            geometry Cylinder {
              height 0.02
              radius 0.04
            }
          }
        ]
        name "solid(1)"
        boundingObject USE robot_wheel
        physics Physics {
        }
        linearVelocity -0.14382589304205856 -3.011579564934739e-05 -0.07021791253949128
        angularVelocity -0.43888182433468104 -0.00028711413210822913 0.8987401777798831
      }
    }
    HingeJoint {
      jointParameters HingeJointParameters {
        position 283.09862102545645
        anchor 0.06 6.27424e-05 -0.05
      }
      device [
        RotationalMotor {
          name "wheel3"
        }
      ]
      endPoint Solid {
        translation 0.05999997793164922 0.00012100811075806523 -0.049978527319441
        rotation -0.17414676661802264 0.174008125513767 -0.9692234396317874 4.681930019462035
        children [
          DEF robot_wheel Shape {
            appearance PBRAppearance {
              baseColor 1 0.643137 0.0235294
              metalness 0
            }
            geometry Cylinder {
              height 0.02
              radius 0.04
            }
          }
        ]
        name "solid(2)"
        boundingObject USE robot_wheel
        physics Physics {
        }
        linearVelocity -0.14380059435112832 4.093647615482418e-05 -0.07023758768747486
        angularVelocity -0.43887397771248354 -0.00028355926514153754 0.898739253714256
      }
    }
    HingeJoint {
      jointParameters HingeJointParameters {
        position 200.29200567899804
        anchor -0.06 6.27012e-05 -0.05
      }
      device [
        RotationalMotor {
          name "wheel4"
        }
      ]
      endPoint Solid {
        translation -0.06000002262936128 0.00010667716163094038 -0.050042829220215385
        rotation -0.35179890832513516 0.3515188492108188 0.8675667275493827 1.7115952569373254
        children [
          DEF robot_wheel Shape {
            appearance PBRAppearance {
              baseColor 1 0.666667 0
              metalness 0
            }
            geometry Cylinder {
              height 0.02
              radius 0.04
            }
          }
        ]
        name "solid(3)"
        boundingObject USE robot_wheel
        physics Physics {
        }
        linearVelocity -0.1437216955575162 -6.616742208330372e-05 -0.07019912290296933
        angularVelocity -0.4388622337405423 -0.00028388892028079963 0.8987156889729988
      }
    }
    DEF body Shape {
      appearance PBRAppearance {
        baseColor 0 1 0
        metalness 0
      }
      geometry Box {
        size 0.1 0.05 0.2
      }
    }
  ]
  boundingObject USE body
  physics Physics {
  }
  controller "object_recognitionc_controller"
  linearVelocity -0.14356780516214576 -9.42687173078001e-05 -0.07010830976977873
  angularVelocity -0.000759436156565868 -4.614977950086389e-05 -0.00018325182157013237
}
