#VRML_SIM R2021b utf8
WorldInfo {
  coordinateSystem "NUE"
  contactProperties [
    ContactProperties {
    }
  ]
}
Viewpoint {
  orientation -0.9998768528679429 0.0095973803297632 0.012416496675958318 0.8844096969327885
  position 0.1856051541140331 10.604765161963345 10.706938243949446
}
Background {
  skyColor [
    1 1 1
  ]
  luminosity 0
}
DEF floorSolid Solid {
  rotation 0 0 1 4.692820414042842e-06
  scale 2 2 2
  children [
    DEF Floor Shape {
      appearance Appearance {
        material Material {
          diffuseColor 0.113725 0.223529 0.337255
          emissiveColor 0.121569 0.247059 0.368627
          specularColor 0.109804 0.223529 0.333333
        }
      }
      geometry Box {
        size 5 0.1 5
      }
    }
  ]
  name "solid(1)"
  boundingObject DEF Floor Shape {
    appearance Appearance {
      material Material {
        diffuseColor 0.113725 0.223529 0.337255
        emissiveColor 0.121569 0.247059 0.368627
        specularColor 0.109804 0.223529 0.333333
      }
    }
    geometry Box {
      size 5 0.1 5
    }
  }
}
DEF wall1 Solid {
  translation 0 0.23 4.93
  scale 2 2 2
  children [
    DEF wall1Shape Shape {
      appearance Appearance {
        material Material {
          diffuseColor 0.666667 0 0
          emissiveColor 0.333333 0.666667 1
        }
      }
      geometry Box {
        size 5 0.3 0.1
      }
    }
  ]
  boundingObject USE wall1Shape
}
DEF wall2 Solid {
  translation -4.9 0.23 0.010002
  rotation 0 1 0 -1.5707953071795862
  scale 2 2 2
  children [
    DEF wall2Shape Shape {
      appearance Appearance {
        material Material {
          emissiveColor 0.333333 0.333333 1
        }
      }
      geometry Box {
        size 5 0.3 0.1
      }
    }
  ]
  boundingObject USE wall2Shape
}
DEF wall3 Solid {
  translation 4.91 0.24 0.00999476
  rotation 0 1 0 -1.5707953071795862
  scale 2 2 2
  children [
    DEF wall3Shape Shape {
      appearance Appearance {
        material Material {
          emissiveColor 0.333333 0.333333 1
        }
      }
      geometry Box {
        size 5 0.3 0.1
      }
    }
  ]
  boundingObject USE wall3Shape
}
DEF wall4 Solid {
  translation 0 0.24 -4.92
  scale 2 2 2
  children [
    DEF wall4Shape Shape {
      appearance Appearance {
        material Material {
          emissiveColor 0.333333 0.333333 1
        }
      }
      geometry Box {
        size 5 0.3 0.1
      }
    }
  ]
  boundingObject USE wall4Shape
}
DirectionalLight {
  direction -1 -1 -1
  castShadows TRUE
}
DEF sylinder Solid {
  translation -0.05 0.48 2.22
  children [
    DEF sylinderShape Shape {
      appearance Appearance {
        material Material {
          emissiveColor 0.556863 0.317647 0.580392
        }
      }
      geometry Cylinder {
        height 1
        radius 0.3
        subdivision 24
      }
    }
  ]
  boundingObject USE sylinderShape
}
DEF sphere Solid {
  translation 4.31247352358406 0.5921722376706797 0.639713187841216
  rotation -0.3423716342370382 0.85379719452233 0.3921887488131935 2.4993590188919312
  children [
    DEF shareShape Shape {
      appearance Appearance {
        material Material {
          emissiveColor 0.556863 0.317647 0.580392
        }
      }
      geometry Sphere {
        radius 0.5
        subdivision 2
      }
    }
  ]
  boundingObject USE shareShape
  physics Physics {
    density -1
    mass 5
  }
}
DEF cone Solid {
  translation -1.6896169512365533 0.609951535111905 -1.6386086254058414
  rotation 0.008621500554236838 0.34786857960471346 -0.9375036645539006 0.0001136183117029299
  children [
    DEF coneShape Shape {
      appearance Appearance {
        material Material {
          emissiveColor 0.556863 0.317647 0.580392
        }
      }
      geometry Cone {
        bottomRadius 0.5
        height 1
      }
    }
  ]
  boundingObject Group {
    children [
      Transform {
        translation 0 -0.31 0
        children [
          Cylinder {
            height 0.4
            radius 0.5
          }
        ]
      }
      Transform {
        translation 0 0.13 0
        children [
          Cylinder {
            height 0.6
            radius 0.2
          }
        ]
      }
    ]
  }
  physics Physics {
    density -1
    mass 0.5
  }
}
DEF wheel Solid {
  translation -0.8 -0.25 -1.93
  children [
    DEF pipe Transform {
      translation 3.47 0.89 0
      children [
        Shape {
          appearance Appearance {
            material Material {
              emissiveColor 0.556863 0.317647 0.580392
            }
          }
          geometry Cylinder {
            height 0.5
            radius 0.2
            subdivision 24
          }
        }
      ]
    }
    DEF wheel1 Transform {
      translation 3.47 0.48 0
      children [
        Shape {
          appearance Appearance {
            material Material {
              emissiveColor 0.556863 0.317647 0.580392
            }
          }
          geometry Cylinder {
            height 0.4
            radius 0.4
            subdivision 24
          }
        }
      ]
    }
  ]
  boundingObject Group {
    children [
      USE wheel1
      USE pipe
    ]
  }
}
Robot {
  translation -0.42898956109425185 0.24141509174269926 -0.18360043244208613
  rotation -0.0046880992091403225 -0.999985942891795 0.0024770435226196263 -0.7552175170611166
  scale 4 4 4
  children [
    DistanceSensor {
      translation 0.02 0 0.1
      rotation 0 -1 0 1.27
      children [
        Shape {
          appearance PBRAppearance {
            baseColor 1 0.666667 0
            metalness 0
          }
          geometry Box {
            size 0.01 0.01 0.01
          }
        }
      ]
      name "ds_right"
      physics Physics {
      }
    }
    DistanceSensor {
      translation -0.02 0 0.1
      rotation 0 -1 0 1.87
      children [
        Shape {
          appearance PBRAppearance {
            baseColor 1 0.666667 0
            metalness 0
          }
          geometry Box {
            size 0.01 0.01 0.01
          }
        }
      ]
      name "ds_left"
      physics Physics {
      }
    }
    HingeJoint {
      jointParameters HingeJointParameters {
        position 11.268054976606335
        anchor -0.06 2.71051e-20 0.05
      }
      device [
        RotationalMotor {
          name "wheel2"
        }
      ]
      endPoint Solid {
        translation -0.06000001884018633 3.433514394218547e-05 0.049876680471684504
        rotation -0.5176362277350783 0.5172241598425837 0.6815657739435949 1.9443581776384553
        children [
          DEF robot_wheel Shape {
            appearance PBRAppearance {
              baseColor 1 0.643137 0.0235294
              metalness 0
            }
            geometry Cylinder {
              height 0.02
              radius 0.04
            }
          }
        ]
        boundingObject USE robot_wheel
        physics Physics {
        }
      }
    }
    HingeJoint {
      jointParameters HingeJointParameters {
        position 36.859901699307954
        anchor 0.06 6.27425e-05 0.05
      }
      device [
        RotationalMotor {
          name "wheel1"
        }
      ]
      endPoint Solid {
        translation 0.05999998171848761 0.00010675983278404797 0.049950795839978024
        rotation -0.3775485983329815 0.37724804065370576 0.8456600804813605 1.7368690383823964
        children [
          DEF robot_wheel Shape {
            appearance PBRAppearance {
              baseColor 1 0.643137 0.0235294
              metalness 0
            }
            geometry Cylinder {
              height 0.02
              radius 0.04
            }
          }
        ]
        name "solid(1)"
        boundingObject USE robot_wheel
        physics Physics {
        }
      }
    }
    HingeJoint {
      jointParameters HingeJointParameters {
        position 36.86043119101445
        anchor 0.06 6.27424e-05 -0.05
      }
      device [
        RotationalMotor {
          name "wheel3"
        }
      ]
      endPoint Solid {
        translation 0.05999997793164922 0.00010414893746803317 -0.05004627599502377
        rotation -0.37735647768859276 0.3770560576935778 0.8458314359865303 1.73666917398818
        children [
          DEF robot_wheel Shape {
            appearance PBRAppearance {
              baseColor 1 0.643137 0.0235294
              metalness 0
            }
            geometry Cylinder {
              height 0.02
              radius 0.04
            }
          }
        ]
        name "solid(2)"
        boundingObject USE robot_wheel
        physics Physics {
        }
      }
    }
    HingeJoint {
      jointParameters HingeJointParameters {
        position 11.267546234330181
        anchor -0.06 6.27012e-05 -0.05
      }
      device [
        RotationalMotor {
          name "wheel4"
        }
      ]
      endPoint Solid {
        translation -0.06000002262936128 7.905745153186336e-05 -0.05005916671650051
        rotation -0.5177632255402167 0.5173510460631151 0.6813729796635549 1.9446215435540792
        children [
          DEF robot_wheel Shape {
            appearance PBRAppearance {
              baseColor 1 0.666667 0
              metalness 0
            }
            geometry Cylinder {
              height 0.02
              radius 0.04
            }
          }
        ]
        name "solid(3)"
        boundingObject USE robot_wheel
        physics Physics {
        }
      }
    }
    DEF body Shape {
      appearance PBRAppearance {
        baseColor 0 1 0
        metalness 0
      }
      geometry Box {
        size 0.1 0.05 0.2
      }
    }
  ]
  boundingObject USE body
  physics Physics {
  }
  controller "object_recognitionc_controller"
}
